<robot name="robovintage">
  
  <material name="vintage">
    <color rgba="0.7 0.7 0.2 1"/>
  </material>

  <link name = "base_lower">
  <visual>
    <origin xyz="0 -0.095 0.025" rpy="0 0 0"/>
    <geometry>
      <box size="0.18 0.29 0.05"/>
    </geometry>
    <material name = "vintage"/>
  </visual>
  </link>

  <link name = "base_upper">
  <visual>
    <origin xyz="0 -0.065 0.14" rpy="0 0 0"/>
    <geometry>
      <box size="0.08 0.23 0.18"/>
    </geometry>
    <material name = "vintage"/>
  </visual>
  </link>

  <joint name="base_joint" type="revolute">
    <axis xyz="0 0 1"/>
    <limit effort="1000.0" lower="-2.618" upper="2.618" velocity="0.5"/>
    <origin rpy="0 0 0" xyz="0 0 0.0"/>    
    <parent link="base_lower"/>
    <child link="base_upper"/>
  </joint>

	<link name = "arm_lower">
  <visual>
    <origin xyz="0 0 0" rpy="0 1.57075 0"/>
    <geometry>
      <cylinder length="0.07" radius="0.04"/>
    </geometry>
    <material name = "vintage"/>
  </visual>
<visual>
    <origin xyz="0 0 0.1" rpy="0 0 0"/>
    <geometry>
      <box size="0.07 0.06 0.2"/>
    </geometry>
    <material name = "vintage"/>
  </visual>
<visual>
    <origin xyz="0 0.0 0.2" rpy="0 1.57075 0"/>
    <geometry>
      <cylinder length="0.07" radius="0.03"/>
    </geometry>
    <material name = "vintage"/>
  </visual>
  </link>

<joint name="arm_lower_joint" type="revolute">
    <axis xyz="1 0 0"/>
    <limit effort="1000.0" lower="-2.356" upper="0.785" velocity="0.5"/>
    <origin rpy="0 0 0" xyz="0 0 0.205"/>    
    <parent link="base_upper"/>
    <child link="arm_lower"/>
  </joint>

<link name = "arm_upper">
  <visual>
    <origin xyz="0 0 0" rpy="0 1.57075 0"/>
    <geometry>
      <cylinder length="0.06" radius="0.03"/>
    </geometry>
    <material name = "vintage"/>
  </visual>
<visual>
    <origin xyz="0 0 0.075" rpy="0 0 0"/>
    <geometry>
      <box size="0.06 0.04 0.15"/>
    </geometry>
    <material name = "vintage"/>
  </visual>
<visual>
    <origin xyz="0 0.0 0.15" rpy="0 1.57075 0"/>
    <geometry>
      <cylinder length="0.06" radius="0.02"/>
    </geometry>
    <material name = "vintage"/>
  </visual>
  </link>

<joint name="arm_upper_joint" type="revolute">
    <axis xyz="1 0 0"/>
    <limit effort="1000.0" lower="-2.356" upper="-0.09" velocity="0.5"/>
    <origin rpy="0 0 0" xyz="0 0 0.2"/>    
    <parent link="arm_lower"/>
    <child link="arm_upper"/>
  </joint>

<link name = "gripper_lower">
  <visual>
    <origin xyz="0 0 0.01" rpy="0 0 0"/>
    <geometry>
      <cylinder length="0.02" radius="0.015"/>
    </geometry>
    <material name = "vintage"/>
  </visual>

  </link>

<joint name="gripper_lower_joint" type="revolute">
    <axis xyz="1 0 0"/>
    <limit effort="1000.0" lower="-1.57" upper="1.57" velocity="0.5"/>
    <origin rpy="0 0 0" xyz="0 0 0.15"/>    
    <parent link="arm_upper"/>
    <child link="gripper_lower"/>
  </joint>

<link name = "gripper_upper">
  <visual>
    <origin xyz="0 0 0.01" rpy="0 0 0"/>
    <geometry>
      <box size="0.08 0.03 0.02"/>
    </geometry>
    <material name = "vintage"/>
  </visual>

  </link>

<joint name="gripper_upper_joint" type="continuous">
    <axis xyz="0 0 1"/>
    <limit effort="1000.0" velocity="0.5"/>
    <origin rpy="0 0 0" xyz="0 0 0.02"/>    
    <parent link="gripper_lower"/>
    <child link="gripper_upper"/>
  </joint>

<link name = "gripper_left">
  <visual>
    <origin xyz="0.005 0.00 0.025" rpy="0 0 0"/>
    <geometry>
      <box size="0.01 0.03 0.05"/>
    </geometry>
    <material name = "vintage"/>
  </visual>
  </link>

<joint name="gripper_left_joint" type="prismatic">
    <axis xyz="1 0 0"/>
    <limit effort="1000.0" lower="0.00" upper="0.03" velocity="0.5"/>
    <origin rpy="0 0 0" xyz="0.00 0.00 0.02"/>    
    <parent link="gripper_upper"/>
    <child link="gripper_left"/>
  </joint>

<link name = "gripper_right">
<visual>
    <origin xyz="-0.005 0.00 0.025" rpy="0 0 0"/>
    <geometry>
      <box size="0.01 0.03 0.05"/>
    </geometry>
    <material name = "vintage"/>
  </visual>
  </link>

<joint name="gripper_right_joint" type="prismatic">
    <axis xyz="-1 0 0"/>
    <limit effort="1000.0" lower="0.0" upper="0.03" velocity="0.5"/>
    <origin rpy="0 0 0" xyz="0 0.00 0.02"/>    
    <parent link="gripper_upper"/>
    <child link="gripper_right"/>
  <mimic joint="gripper_left_joint"/>
  </joint>

</robot>
